Workbook

Sheet Summary
A1: UeCampus — SEO keywords for every page
A2: Generated 2026-09-22 from the live site source. https://uecampus.com
A4: Counts
A5: Pages in this workbook | B5: =COUNTA('All Pages'!A2:A147)
A6: Site pages | B6: =COUNTIF('All Pages'!A2:A147,"Site page")
A7: Programme pages | B7: =COUNTIF('All Pages'!A2:A147,"Programme")
A8: Partner pages | B8: =COUNTIF('All Pages'!A2:A147,"Partner")
A9: Keyword entries in total | B9: =COUNTA(Keywords!A2:A622)
A10: Unique keywords | B10: =COUNTA('Keyword Index'!A2:A355)
A11: Average keywords per page | B11: =ROUND(COUNTA(Keywords!A2:A622)/COUNTA('All Pages'!A2:A147),1)
A13: Sheets
A14: All Pages | C14: Every page with its title tag, meta description and full keyword list. One row per URL.
A15: Keywords | C15: Every keyword on its own row, A–Z, with the page it belongs to. 'Position on page' is its order within that page's keyword list.
A16: Keyword Index | C16: Each unique keyword once, with how many pages use it — sorted most-used first, so overlap between pages is visible at a glance.
A18: Where each keyword comes from
A19: courseSeoOverrides.ts (keyword map) | B19: 110 | C19: Hand-written per programme, imported from the keyword map spreadsheet.
A20: generated from course data | B20: 17 | C20: No keyword-map row for this programme, so the site builds the keywords from its title, level, awarding body and subject categories.
A21: siteMeta.ts | B21: 13 | C21: Hand-written per site page.
A22: generated from partner data | B22: 5 | C22: Built from the partner's name.
A23: blog/index.php | B23: 1 | C23: Hand-written in the blog's PHP template.
A25: These are the keywords the site serves today — read from the same source files the pages render from, so a row here matches that page's <meta name="keywords"> exactly.
A26: Programme rows include the 33 pages hidden from listings or canonicalised to another programme; the Notes column on 'All Pages' flags each one.
A27: Editing this workbook does not change the website. Keywords are edited in the admin console under SEO tags, or in the source files named in the 'Keyword source' column.

Sheet All Pages
A1: Group | B1: Page / Programme | C1: URL | D1: Title tag | E1: Meta description | F1: Keywords | G1: # Keywords | H1: Level | I1: Awarding body | J1: Keyword source | K1: Notes
A2: Site page | B2: About UeCampus | C2: https://uecampus.com/about-us | D2: About UeCampus | Online Higher Education Platform | E2: UeCampus delivers internationally recognised online degrees with partners across the USA, France, Europe and UK. Meet the team behind Degrees Without Barriers. | F2: about uecampus, uecampus reviews, uecampus online university | G2: =IF(TRIM(F2)="",0,LEN(TRIM(F2))-LEN(SUBSTITUTE(TRIM(F2),",",""))+1) | J2: siteMeta.ts
A3: Site page | B3: Accreditation & University Partners | C3: https://uecampus.com/accreditation-and-partners | D3: Accreditation & University Partners | UeCampus | E3: How UeCampus programmes are accredited: Walsh College (HLC, ACBSP), PPA Business School, eie, Qualifi. Verify every credential on official registers. | F3: uecampus accreditation, is uecampus accredited, is uecampus legit, walsh college accreditation | G3: =IF(TRIM(F3)="",0,LEN(TRIM(F3))-LEN(SUBSTITUTE(TRIM(F3),",",""))+1) | J3: siteMeta.ts
A4: Site page | B4: All Programmes | C4: https://uecampus.com/programmes | D4: All Programmes | Bachelors, Masters, MBA, DBA | UeCampus | E4: Full catalogue of internationally recognised online programmes from Walsh College, PPA Business School, eie and UK awarding bodies. Compare levels, fees and diplomas. | F4: online degree programmes, university programmes online, postgraduate programmes online | G4: =IF(TRIM(F4)="",0,LEN(TRIM(F4))-LEN(SUBSTITUTE(TRIM(F4),",",""))+1) | J4: siteMeta.ts
A5: Site page | B5: Blog (journal index) | C5: https://uecampus.com/blog | D5: Blog | Online Study, Careers & Qualifications | UeCampus | E5: Guides on online study, UK qualifications, career growth and degree recognition from the UeCampus academic team. | F5: online education blog, distance learning tips, online study advice, uecampus blog | G5: =IF(TRIM(F5)="",0,LEN(TRIM(F5))-LEN(SUBSTITUTE(TRIM(F5),",",""))+1) | J5: blog/index.php
A6: Site page | B6: Contact UeCampus | C6: https://uecampus.com/contact-us | D6: Contact UeCampus | Speak to an Admissions Advisor | E6: Talk to a UeCampus admissions advisor about programmes, fees and the September 2026 intake. WhatsApp, phone and email support. | F6: contact uecampus, uecampus whatsapp, uecampus admissions | G6: =IF(TRIM(F6)="",0,LEN(TRIM(F6))-LEN(SUBSTITUTE(TRIM(F6),",",""))+1) | J6: siteMeta.ts
A7: Site page | B7: Enquire Now | C7: https://uecampus.com/enquire-now | D7: Enquire Now | Start Your Online Degree | UeCampus | E7: Request programme details, fees and entry requirements. An advisor responds within 24 hours. September 2026 intake - places limited. | F7: apply online degree, enrol online university, online degree application | G7: =IF(TRIM(F7)="",0,LEN(TRIM(F7))-LEN(SUBSTITUTE(TRIM(F7),",",""))+1) | J7: siteMeta.ts
A8: Site page | B8: Online Degree Programmes & UK Diplomas | C8: https://uecampus.com/courses | D8: Online Degree Programmes & UK Diplomas | UeCampus | E8: Browse internationally recognised online programmes: BBA, BSc, MBA, DBA and UK Level 2-8 diplomas. Study anywhere, graduate with a recognised qualification. | F8: online courses and degree programmes, online degree programmes, recognised online courses | G8: =IF(TRIM(F8)="",0,LEN(TRIM(F8))-LEN(SUBSTITUTE(TRIM(F8),",",""))+1) | J8: siteMeta.ts
A9: Site page | B9: Online Degrees FAQ | C9: https://uecampus.com/faqs | D9: Online Degrees FAQ | Recognition, Fees & Study | UeCampus | E9: Answers to common questions about studying online with UeCampus: recognition, attestation, fees, assessments and graduation. | F9: online degree faq, how do online degrees work, are online degrees recognised | G9: =IF(TRIM(F9)="",0,LEN(TRIM(F9))-LEN(SUBSTITUTE(TRIM(F9),",",""))+1) | J9: siteMeta.ts
A10: Site page | B10: Online Degrees Without Barriers | C10: https://uecampus.com/ | D10: Online Degrees Without Barriers | Flexible & Affordable | UeCampus | E10: Study 100% online with UeCampus. Internationally recognised bachelors, masters, MBA, DBA & UK diplomas from partner institutions. Flexible fees. Sept 2026 intake open. | F10: online degrees, online university, affordable online degrees, distance learning degrees | G10: =IF(TRIM(F10)="",0,LEN(TRIM(F10))-LEN(SUBSTITUTE(TRIM(F10),",",""))+1) | J10: siteMeta.ts
A11: Site page | B11: Our Team | C11: https://uecampus.com/team | D11: Our Team | The People Behind UeCampus | E11: Meet the people behind UeCampus — the academics, advisors and support team helping students earn internationally recognised online degrees. | F11: uecampus team, uecampus staff, uecampus leadership, meet the team | G11: =IF(TRIM(F11)="",0,LEN(TRIM(F11))-LEN(SUBSTITUTE(TRIM(F11),",",""))+1) | J11: siteMeta.ts
A12: Site page | B12: Page Not Found | C12: https://uecampus.com/404 | D12: Page Not Found | UeCampus | E12: The page you were looking for could not be found. Explore UeCampus online programmes, accreditation and admissions instead. | F12: UeCampus, page not found | G12: =IF(TRIM(F12)="",0,LEN(TRIM(F12))-LEN(SUBSTITUTE(TRIM(F12),",",""))+1) | J12: siteMeta.ts
A13: Site page | B13: Scholarships for Online Students | C13: https://uecampus.com/scholarship | D13: Scholarships for Online Students | UeCampus | E13: Apply for the Academic Excellence or Developing Country Scholarship and reduce the cost of your online degree with UeCampus. | F13: online degree scholarships, scholarships for online students, developing country scholarship | G13: =IF(TRIM(F13)="",0,LEN(TRIM(F13))-LEN(SUBSTITUTE(TRIM(F13),",",""))+1) | J13: siteMeta.ts
... A15: Site page | B15: Tuition & Fees | C15: https://uecampus.com/fees | D15: Tuition & Fees | Online Degree Costs | UeCampus | E15: Transparent tuition fees for internationally recognised online degrees from Walsh College, eie and PPA Business School. Compare bachelor, master and PhD programme costs. | F15: online degree fees, tuition fees, walsh college fees, eie fees, ppa business school fees | G15: =IF(TRIM(F15)="",0,LEN(TRIM(F15))-LEN(SUBSTITUTE(TRIM(F15),",",""))+1) | J15: siteMeta.ts
A16: Programme | B16: BA (Hons) in Business Management (BBA) | C16: https://uecampus.com/programmes/bba-business-management-eie | D16: Online BBA Business Management | eie Malta | UeCampus | E16: Accredited European BBA Business Management delivered 100% online through eie European Business School. Flexible, affordable, globally recognised. | F16: online bba business management, bba business management eie european business school, european degree online, MQF accredited degree | G16: =IF(TRIM(F16)="",0,LEN(TRIM(F16))-LEN(SUBSTITUTE(TRIM(F16),",",""))+1) | H16: Bachelor's | I16: eie Business School | J16: courseSeoOverrides.ts (keyword map)
A17: Programme | B17: Bachelor of Arts in Accountancy and Finance | C17: https://uecampus.com/programmes/bachelor-of-arts-in-accountancy-and-finance-eie-european-business-school | D17: Bachelor of Arts in Accountancy and Finance | eie | UeCampus | E17: Accredited European Bachelor of Arts in Accountancy and Finance delivered 100% online through eie European Business School. Flexible, affordable | F17: online bachelor of arts in accountancy and finance, bachelor of arts in accountancy and finance eie european business school, european degree online, MQF accredited degree | G17: =IF(TRIM(F17)="",0,LEN(TRIM(F17))-LEN(SUBSTITUTE(TRIM(F17),",",""))+1) | H17: Bachelor's | I17: eie Business School | J17: courseSeoOverrides.ts (keyword map)
A18: Programme | B18: Bachelor of Arts in Business Managment | C18: https://uecampus.com/programmes/bachelor-of-arts-in-business-managment---eie-european-business-school | D18: Bachelor of Arts in Business Managment | eie | UeCampus | E18: Accredited European Bachelor of Arts in Business Managment delivered 100% online through eie European Business School. Flexible, affordable, globally | F18: online bachelor of arts in business managment, bachelor of arts in business managment eie european business school, european degree online, MQF accredited degree | G18: =IF(TRIM(F18)="",0,LEN(TRIM(F18))-LEN(SUBSTITUTE(TRIM(F18),",",""))+1) | H18: Bachelor's | I18: eie Business School | J18: courseSeoOverrides.ts (keyword map) | K18: hidden from listings · canonical: /programmes/bba-business-management-eie
A19: Programme | B19: Bachelor of Business Administration (BBA) | C19: https://uecampus.com/programmes/bachelor-of-business-administration-bba | D19: Online Bachelor of Business Administration BBA | UeCampus | E19: Study a recognised Bachelor of Business Administration BBA 100% online with UeCampus. Flexible schedules, monthly instalments and full tutor support. | F19: online bachelor of business administration bba, recognised bachelor of business administration bba online, bachelor of business administration bba distance learning, affordable bachelor of business administration bba | G19: =IF(TRIM(F19)="",0,LEN(TRIM(F19))-LEN(SUBSTITUTE(TRIM(F19),",",""))+1) | H19: Bachelor's | I19: Walsh College | J19: courseSeoOverrides.ts (keyword map) | K19: hidden from listings · canonical: /programmes/bba-walsh
A20: Programme | B20: Bachelor of Business Administration (BBA) | C20: https://uecampus.com/programmes/bachelor-of-business-administration-bba-direct | D20: Online Bachelor of Business Administration BBA | UeCampus | E20: Study a recognised Bachelor of Business Administration BBA 100% online with UeCampus. Flexible schedules, monthly instalments and full tutor support. | F20: online bachelor of business administration bba, recognised bachelor of business administration bba online, bachelor of business administration bba distance learning, affordable bachelor of business administration bba | G20: =IF(TRIM(F20)="",0,LEN(TRIM(F20))-LEN(SUBSTITUTE(TRIM(F20),",",""))+1) | H20: Bachelor's | I20: Walsh College Direct | J20: courseSeoOverrides.ts (keyword map) | K20: hidden from listings · canonical: /programmes/bba-walsh
A21: Programme | B21: Bachelor of Business Administration in Human Resource Management | C21: https://uecampus.com/programmes/bba-human-resource-management-walsh | D21: BBA Human Resource Management Online | Walsh | UeCampus | E21: Earn an accredited BBA Human Resource Management 100% online from Walsh College USA (HLC & ACBSP accredited). Flexible study, monthly instalments, Sept | F21: online bba human resource management, bba human resource management walsh college, accredited american bba human resource management online, US degree online | G21: =IF(TRIM(F21)="",0,LEN(TRIM(F21))-LEN(SUBSTITUTE(TRIM(F21),",",""))+1) | H21: Bachelor's | I21: Walsh College Direct | J21: courseSeoOverrides.ts (keyword map)
A22: Programme | B22: Bachelor of Business Administration in Human Resource Management | C22: https://uecampus.com/programmes/bba-human-resource-management-walsh-uecampus | D22: BBA Human Resource Management Online | Walsh | UeCampus | E22: Earn an accredited BBA Human Resource Management 100% online from Walsh College USA (HLC & ACBSP accredited). Flexible study, monthly instalments, Sept | F22: online bba human resource management, bba human resource management walsh college, accredited american bba human resource management online, US degree online | G22: =IF(TRIM(F22)="",0,LEN(TRIM(F22))-LEN(SUBSTITUTE(TRIM(F22),",",""))+1) | H22: Bachelor's | I22: Walsh College | J22: courseSeoOverrides.ts (keyword map)
A23: Programme | B23: Bachelor of Science in Cyber Security | C23: https://uecampus.com/programmes/bsc-cyber-security-walsh | D23: Online BSc Cyber Security | Walsh College USA | UeCampus | E23: Earn an accredited BSc Cyber Security 100% online from Walsh College USA (HLC & ACBSP accredited). Flexible study, monthly instalments, Sept 2026 intake. | F23: online bsc cyber security, bsc cyber security walsh college, accredited american bsc cyber security online, US degree online | G23: =IF(TRIM(F23)="",0,LEN(TRIM(F23))-LEN(SUBSTITUTE(TRIM(F23),",",""))+1) | H23: Bachelor's | I23: Walsh College Direct | J23: courseSeoOverrides.ts (keyword map)
A24: Programme | B24: Bachelor of Science in Cyber Security | C24: https://uecampus.com/programmes/bsc-cyber-security-walsh-uecampus | D24: Online BSc Cyber Security | Walsh College USA | UeCampus | E24: Earn an accredited BSc Cyber Security 100% online from Walsh College USA (HLC & ACBSP accredited). Flexible study, monthly instalments, Sept 2026 intake. | F24: online bsc cyber security, bsc cyber security walsh college, accredited american bsc cyber security online, US degree online | G24: =IF(TRIM(F24)="",0,LEN(TRIM(F24))-LEN(SUBSTITUTE(TRIM(F24),",",""))+1) | H24: Bachelor's | I24: Walsh College | J24: courseSeoOverrides.ts (keyword map)
A25: Programme | B25: Bachelor's in Accounting | C25: https://uecampus.com/programmes/bachelors-in-accounting | D25: Online Bachelors in Accounting | Recognised | UeCampus | E25: Study a recognised Bachelors in Accounting 100% online with UeCampus. Flexible schedules, monthly instalments and full tutor support. Sept 2026 intake | F25: online bachelors in accounting, recognised bachelors in accounting online, bachelors in accounting distance learning, affordable bachelors in accounting | G25: =IF(TRIM(F25)="",0,LEN(TRIM(F25))-LEN(SUBSTITUTE(TRIM(F25),",",""))+1) | H25: Bachelor's | I25: Walsh College | J25: courseSeoOverrides.ts (keyword map) | K25: hidden from listings · canonical: /programmes/bba-in-accounting
A26: Programme | B26: Bachelor's in Accounting | C26: https://uecampus.com/programmes/bachelors-in-accounting-direct | D26: Online Bachelors in Accounting | Recognised | UeCampus | E26: Study a recognised Bachelors in Accounting 100% online with UeCampus. Flexible schedules, monthly instalments and full tutor support. Sept 2026 intake | F26: online bachelors in accounting, recognised bachelors in accounting online, bachelors in accounting distance learning, affordable bachelors in accounting | G26: =IF(TRIM(F26)="",0,LEN(TRIM(F26))-LEN(SUBSTITUTE(TRIM(F26),",",""))+1) | H26: Bachelor's | I26: Walsh College Direct | J26: courseSeoOverrides.ts (keyword map) | K26: hidden from listings · canonical: /programmes/bba-in-accounting-direct
A27: Programme | B27: Bachelor's in Data Analytics | C27: https://uecampus.com/programmes/bachelors-in-data-analytics | D27: Online Bachelors in Data Analytics | Recognised | UeCampus | E27: Study a recognised Bachelors in Data Analytics 100% online with UeCampus. Flexible schedules, monthly instalments and full tutor support. Sept 2026 | F27: online bachelors in data analytics, recognised bachelors in data analytics online, bachelors in data analytics distance learning, affordable bachelors in data analytics | G27: =IF(TRIM(F27)="",0,LEN(TRIM(F27))-LEN(SUBSTITUTE(TRIM(F27),",",""))+1) | H27: Bachelor's | I27: Walsh College | J27: courseSeoOverrides.ts (keyword map) | K27: hidden from listings · canonical: /programmes/bsc-in-data-analytics
A28: Programme | B28: Bachelor's in Data Analytics | C28: https://uecampus.com/programmes/bachelors-in-data-analytics-direct | D28: Online Bachelors in Data Analytics | Recognised | UeCampus | E28: Study a recognised Bachelors in Data Analytics 100% online with UeCampus. Flexible schedules, monthly instalments and full tutor support. Sept 2026 | F28: online bachelors in data analytics, recognised bachelors in data analytics online, bachelors in data analytics distance learning, affordable bachelors in data analytics | G28: =IF(TRIM(F28)="",0,LEN(TRIM(F28))-LEN(SUBSTITUTE(TRIM(F28),",",""))+1) | H28: Bachelor's | I28: Walsh College Direct | J28: courseSeoOverrides.ts (keyword map) | K28: hidden from listings · canonical: /programmes/bsc-in-data-analytics-direct
A29: Programme | B29: Bachelor's in Entrepreneurship | C29: https://uecampus.com/programmes/bachelors-in-entrepreneurship | D29: Online Bachelors in Entrepreneurship | Recognised | UeCampus | E29: Study a recognised Bachelors in Entrepreneurship 100% online with UeCampus. Flexible schedules, monthly instalments and full tutor support. Sept 2026 | F29: online bachelors in entrepreneurship, recognised bachelors in entrepreneurship online, bachelors in entrepreneurship distance learning, affordable bachelors in entrepreneurship | G29: =IF(TRIM(F29)="",0,LEN(TRIM(F29))-LEN(SUBSTITUTE(TRIM(F29),",",""))+1) | H29: Bachelor's | I29: Walsh College | J29: courseSeoOverrides.ts (keyword map) | K29: hidden from listings · canonical: /programmes/bba-in-entrepreneurship
A30: Programme | B30: Bachelor's in Entrepreneurship | C30: https://uecampus.com/programmes/bachelors-in-entrepreneurship-direct | D30: Online Bachelors in Entrepreneurship | Recognised | UeCampus | E30: Study a recognised Bachelors in Entrepreneurship 100% online with UeCampus. Flexible schedules, monthly instalments and full tutor support. Sept 2026 | F30: online bachelors in entrepreneurship, recognised bachelors in entrepreneurship online, bachelors in entrepreneurship distance learning, affordable bachelors in entrepreneurship | G30: =IF(TRIM(F30)="",0,LEN(TRIM(F30))-LEN(SUBSTITUTE(TRIM(F30),",",""))+1) | H30: Bachelor's | I30: Walsh College Direct | J30: courseSeoOverrides.ts (keyword map) | K30: hidden from listings · canonical: /programmes/bba-in-entrepreneurship-direct
A31: Programme | B31: Bachelors of Arts in Tourism and Hospitality Management | C31: https://uecampus.com/programmes/bachelors-of-arts-in-tourism-and-hospitality-management-eie-european-business-school | D31: Bachelors of Arts in Tourism and Hospitality Management | ei | E31: Accredited European Bachelors of Arts in Tourism and Hospitality Management delivered 100% online through eie European Business School. Flexible | F31: online bachelors of arts in tourism and hospitality management, bachelors of arts in tourism and hospitality management eie european business school, european degree online, MQF accredited degree | G31: =IF(TRIM(F31)="",0,LEN(TRIM(F31))-LEN(SUBSTITUTE(TRIM(F31),",",""))+1) | H31: Bachelor's | I31: eie Business School | J31: courseSeoOverrides.ts (keyword map)
A32: Programme | B32: BBA for ACCA | C32: https://uecampus.com/programmes/bba-for-acca | D32: BBA for ACCA | Walsh College | UeCampus | E32: BBA for ACCA delivered 100% online through Walsh College. Flexible, affordable and globally recognised. Sept 2026 intake. | F32: BBA for ACCA, online BBA for ACCA, Bachelor's online, Walsh College, Accounting, recognised online degree, UeCampus | G32: =IF(TRIM(F32)="",0,LEN(TRIM(F32))-LEN(SUBSTITUTE(TRIM(F32),",",""))+1) | H32: Bachelor's | I32: Walsh College | J32: generated from course data | K32: hidden from listings
A33: Programme | B33: BBA for ACCA | C33: https://uecampus.com/programmes/bba-for-acca-direct | D33: BBA for ACCA | Walsh College Direct | UeCampus | E33: BBA for ACCA delivered 100% online through Walsh College. Flexible, affordable and globally recognised. Sept 2026 intake. | F33: BBA for ACCA, online BBA for ACCA, Bachelor's online, Walsh College, Accounting, recognised online degree, UeCampus | G33: =IF(TRIM(F33)="",0,LEN(TRIM(F33))-LEN(SUBSTITUTE(TRIM(F33),",",""))+1) | H33: Bachelor's | I33: Walsh College Direct | J33: generated from course data | K33: hidden from listings
A34: Programme | B34: BBA in Accounting | C34: https://uecampus.com/programmes/bba-in-accounting | D34: BBA in Accounting | Walsh College | UeCampus | E34: BBA in Accounting delivered 100% online through Walsh College. Flexible, affordable and globally recognised. Sept 2026 intake. | F34: BBA in Accounting, online BBA in Accounting, Bachelor's online, Walsh College, Accounting, recognised online degree, UeCampus | G34: =IF(TRIM(F34)="",0,LEN(TRIM(F34))-LEN(SUBSTITUTE(TRIM(F34),",",""))+1) | H34: Bachelor's | I34: Walsh College | J34: generated from course data
A35: Programme | B35: BBA in Accounting | C35: https://uecampus.com/programmes/bba-in-accounting-direct | D35: BBA in Accounting | Walsh College Direct | UeCampus | E35: BBA in Accounting delivered 100% online through Walsh College. Flexible, affordable and globally recognised. Sept 2026 intake. | F35: BBA in Accounting, online BBA in Accounting, Bachelor's online, Walsh College, Accounting, recognised online degree, UeCampus | G35: =IF(TRIM(F35)="",0,LEN(TRIM(F35))-LEN(SUBSTITUTE(TRIM(F35),",",""))+1) | H35: Bachelor's | I35: Walsh College Direct | J35: generated from course data
A36: Programme | B36: BBA in Entrepreneurship | C36: https://uecampus.com/programmes/bba-in-entrepreneurship | D36: BBA in Entrepreneurship | Walsh College | UeCampus | E36: BBA in Entrepreneurship delivered 100% online through Walsh College. Flexible, affordable and globally recognised. Sept 2026 intake. | F36: BBA in Entrepreneurship, online BBA in Entrepreneurship, Bachelor's online, Walsh College, Entrepreneurship, recognised online degree, UeCampus | G36: =IF(TRIM(F36)="",0,LEN(TRIM(F36))-LEN(SUBSTITUTE(TRIM(F36),",",""))+1) | H36: Bachelor's | I36: Walsh College | J36: generated from course data
A37: Programme | B37: BBA in Entrepreneurship | C37: https://uecampus.com/programmes/bba-in-entrepreneurship-direct | D37: BBA in Entrepreneurship | Walsh College Direct | UeCampus | E37: BBA in Entrepreneurship delivered 100% online through Walsh College. Flexible, affordable and globally recognised. Sept 2026 intake. | F37: BBA in Entrepreneurship, online BBA in Entrepreneurship, Bachelor's online, Walsh College, Entrepreneurship, recognised online degree, UeCampus | G37: =IF(TRIM(F37)="",0,LEN(TRIM(F37))-LEN(SUBSTITUTE(TRIM(F37),",",""))+1) | H37: Bachelor's | I37: Walsh College Direct | J37: generated from course data
A38: Programme | B38: BBA in Finance | C38: https://uecampus.com/programmes/bba-finance-walsh | D38: Online BBA Finance | Walsh College USA | UeCampus | E38: Earn an accredited BBA Finance 100% online from Walsh College USA (HLC & ACBSP accredited). Flexible study, monthly instalments, Sept 2026 intake. | F38: online bba finance, bba finance walsh college, accredited american bba finance online, US degree online | G38: =IF(TRIM(F38)="",0,LEN(TRIM(F38))-LEN(SUBSTITUTE(TRIM(F38),",",""))+1) | H38: Bachelor's | I38: Walsh College Direct | J38: courseSeoOverrides.ts (keyword map)
A39: Programme | B39: BBA in Finance | C39: https://uecampus.com/programmes/bba-finance-walsh-uecampus | D39: Online BBA Finance | Walsh College USA | UeCampus | E39: Earn an accredited BBA Finance 100% online from Walsh College USA (HLC & ACBSP accredited). Flexible study, monthly instalments, Sept 2026 intake. | F39: online bba finance, bba finance walsh college, accredited american bba finance online, US degree online | G39: =IF(TRIM(F39)="",0,LEN(TRIM(F39))-LEN(SUBSTITUTE(TRIM(F39),",",""))+1) | H39: Bachelor's | I39: Walsh College | J39: courseSeoOverrides.ts (keyword map)
A40: Programme | B40: BBA in General Business | C40: https://uecampus.com/programmes/bba-in-general-business | D40: Online BBA in General Business | Recognised | UeCampus | E40: Study a recognised BBA in General Business 100% online with UeCampus. Flexible schedules, monthly instalments and full tutor support. Sept 2026 intake | F40: online bba in general business, recognised bba in general business online, bba in general business distance learning, affordable bba in general business | G40: =IF(TRIM(F40)="",0,LEN(TRIM(F40))-LEN(SUBSTITUTE(TRIM(F40),",",""))+1) | H40: Bachelor's | I40: Walsh College | J40: courseSeoOverrides.ts (keyword map) | K40: hidden from listings · canonical: /programmes/bba-walsh
A41: Programme | B41: BBA in General Business | C41: https://uecampus.com/programmes/bba-in-general-business-direct | D41: Online BBA in General Business | Recognised | UeCampus | E41: Study a recognised BBA in General Business 100% online with UeCampus. Flexible schedules, monthly instalments and full tutor support. Sept 2026 intake | F41: online bba in general business, recognised bba in general business online, bba in general business distance learning, affordable bba in general business | G41: =IF(TRIM(F41)="",0,LEN(TRIM(F41))-LEN(SUBSTITUTE(TRIM(F41),",",""))+1) | H41: Bachelor's | I41: Walsh College Direct | J41: courseSeoOverrides.ts (keyword map) | K41: hidden from listings · canonical: /programmes/bba-walsh
...

Sheet Keywords
A1: Keyword | B1: Group | C1: Page / Programme | D1: URL | E1: Position on page | F1: Title tag
A2: about uecampus | B2: Site page | C2: About UeCampus | D2: https://uecampus.com/about-us | E2: 1 | F2: About UeCampus | Online Higher Education Platform
A3: Accounting | B3: Programme | C3: BBA for ACCA | D3: https://uecampus.com/programmes/bba-for-acca | E3: 5 | F3: BBA for ACCA | Walsh College | UeCampus
A4: Accounting | B4: Programme | C4: BBA for ACCA | D4: https://uecampus.com/programmes/bba-for-acca-direct | E4: 5 | F4: BBA for ACCA | Walsh College Direct | UeCampus
A5: Accounting | B5: Programme | C5: BBA in Accounting | D5: https://uecampus.com/programmes/bba-in-accounting | E5: 5 | F5: BBA in Accounting | Walsh College | UeCampus
A6: Accounting | B6: Programme | C6: BBA in Accounting | D6: https://uecampus.com/programmes/bba-in-accounting-direct | E6: 5 | F6: BBA in Accounting | Walsh College Direct | UeCampus
A7: Accounting | B7: Programme | C7: DBA in Accounting and Finance | D7: https://uecampus.com/programmes/doctorate-in-business-dba | E7: 5 | F7: DBA in Accounting and Finance | UeCampus
A8: Accounting | B8: Programme | C8: DBA in Accounting and Finance | D8: https://uecampus.com/programmes/doctorate-in-business-dba-uecampus | E8: 5 | F8: DBA in Accounting and Finance | Walsh College | UeCampus
A9: accredited american bba finance online | B9: Programme | C9: BBA in Finance | D9: https://uecampus.com/programmes/bba-finance-walsh | E9: 3 | F9: Online BBA Finance | Walsh College USA | UeCampus
A10: accredited american bba finance online | B10: Programme | C10: BBA in Finance | D10: https://uecampus.com/programmes/bba-finance-walsh-uecampus | E10: 3 | F10: Online BBA Finance | Walsh College USA | UeCampus
A11: accredited american bba human resource management online | B11: Programme | C11: Bachelor of Business Administration in Human Resource Management | D11: https://uecampus.com/programmes/bba-human-resource-management-walsh | E11: 3 | F11: BBA Human Resource Management Online | Walsh | UeCampus
A12: accredited american bba human resource management online | B12: Programme | C12: Bachelor of Business Administration in Human Resource Management | D12: https://uecampus.com/programmes/bba-human-resource-management-walsh-uecampus | E12: 3 | F12: BBA Human Resource Management Online | Walsh | UeCampus
A13: accredited american bba international business online | B13: Programme | C13: BBA in International Business | D13: https://uecampus.com/programmes/bba-international-business-walsh | E13: 3 | F13: Online BBA International Business | Walsh College | UeCampus
... A622: Walsh College online degree | B622: Partner | C622: Walsh College | D622: https://uecampus.com/partners/walsh-college | E622: 3 | F622: Walsh College | UeCampus Partner

Sheet Keyword Index
A1: Keyword (unique) | B1: Pages using it | C1: Groups | D1: Pages
A2: US degree online | B2: =COUNTIF(Keywords!$A$2:$A$622,A2) | C2: Programme | D2: BBA in Finance; BBA in International Business; BBA in Marketing; BBA, Bachelor of Business Administration; BSc in Information Technology (BSIT); Bachelor of Business Administration in Human Resource Management (+8 more)
A3: UeCampus | B3: =COUNTIF(Keywords!$A$2:$A$622,A3) | C3: Programme, Site page | D3: BBA for ACCA; BBA in Accounting; BBA in Entrepreneurship; DBA in Accounting and Finance; Level 7 Diploma in Education Management and Leadership; MSc in Finance (+6 more)
A4: recognised online degree | B4: =COUNTIF(Keywords!$A$2:$A$622,A4) | C4: Programme | D4: BBA for ACCA; BBA in Accounting; BBA in Entrepreneurship; DBA in Accounting and Finance; Level 7 Diploma in Education Management and Leadership; MSc in Finance (+4 more)
A5: Walsh College | B5: =COUNTIF(Keywords!$A$2:$A$622,A5) | C5: Partner, Programme | D5: BBA for ACCA; BBA in Accounting; BBA in Entrepreneurship; DBA in Accounting and Finance; MSc in Finance; Master of Business Administration Degree (MBA) (+2 more)
A6: european degree online | B6: =COUNTIF(Keywords!$A$2:$A$622,A6) | C6: Programme | D6: BA (Hons) in Business Management (BBA); Bachelor of Arts in Accountancy and Finance; Bachelor of Arts in Business Managment; Bachelors of Arts in Tourism and Hospitality Management; MBA in Accounting and Finance; Master of Business Administration (MBA) (+2 more)
A7: MQF accredited degree | B7: =COUNTIF(Keywords!$A$2:$A$622,A7) | C7: Programme | D7: BA (Hons) in Business Management (BBA); Bachelor of Arts in Accountancy and Finance; Bachelor of Arts in Business Managment; Bachelors of Arts in Tourism and Hospitality Management; MBA in Accounting and Finance; Master of Business Administration (MBA) (+2 more)
A8: Business | B8: =COUNTIF(Keywords!$A$2:$A$622,A8) | C8: Programme | D8: DBA in Accounting and Finance; Master of Business Administration Degree (MBA); Master's in Business Administration (MBA); Qualifi Level 8 Diploma in Strategic Management and Leadership (Business Administration)
A9: Accounting | B9: =COUNTIF(Keywords!$A$2:$A$622,A9) | C9: Programme | D9: BBA for ACCA; BBA in Accounting; DBA in Accounting and Finance
A10: Bachelor's online | B10: =COUNTIF(Keywords!$A$2:$A$622,A10) | C10: Programme | D10: BBA for ACCA; BBA in Accounting; BBA in Entrepreneurship
A11: Master's online | B11: =COUNTIF(Keywords!$A$2:$A$622,A11) | C11: Programme | D11: MSc in Finance; Master of Business Administration Degree (MBA); Master's in Business Administration (MBA)
A12: uecampus partners | B12: =COUNTIF(Keywords!$A$2:$A$622,A12) | C12: Partner | D12: EduQual; PPA Business School; Qualifi; Walsh College; eie European Business School
A13: Finance | B13: =COUNTIF(Keywords!$A$2:$A$622,A13) | C13: Programme | D13: DBA in Accounting and Finance; MSc in Finance
... A355: Walsh College online degree | B355: =COUNTIF(Keywords!$A$2:$A$622,A355) | C355: Partner | D355: Walsh College
